---
aliases:
  - Traceback
tags:
  - python
  - python_debugger
---
%%
cData:: `=dateformat(this.file.ctime, "dd-MM-yyyy")`
mData:: `=dateformat(this.file.mtime, "dd-MM-yyyy")`
%%

___
# Traceback

"Uma maneira graciosa", foi como eu me referi à forma como as [[Exceções|exceções]] lidam com eventos anormais que interrompem o fluxo de execução do programa. Disse isso porque, de fato, o Python nos faz um grande favor (quando digo "Python", me refiro ao interpretador da linguagem): Ele nos dá uma _mapa_ que nos guia até o local que levantou a exceção. Em outras palavras, ele nos mostra onde está o erro. Ele tenta fazer isso da melhor maneira possível, mas do jeito dele. 

Quando uma exceção ocorre, nos deparamos com uma mensagem semelhante a essa:

```shell
Traceback (most recent call last):
  File "/home/tiago/workspace/Python/debug_example_fatorial.py", line 20, in <module>
    main()
  File "/home/tiago/workspace/Python/debug_example_fatorial.py", line 16, in main
    return map_fatorial(numbers=numbers)
           ^^^^^^^^^^^^^^^^^^^^^^^^^^^^^
  File "/home/tiago/workspace/Python/debug_example_fatorial.py", line 7, in map_fatorial
    result.append(factorial(num))
                  ^^^^^^^^^^^^^^
ValueError: factorial() not defined for negative values
```

Um `traceback` é um relatório que contém as chamadas de função feitas por seu código até um ponto específico. Se você não souber ler o `traceback` perderá muitas informações importantes que podem ser úteis para compreender o problema. Mas, quando você o lê corretamente, poderá entender o problema sem sequer quer  abrir o código. Considere a figura abaixo:


![[traceback_py.jpg]]


1. **Leia sempre de baixo para cima**: Nem sempre o traceback será curto como o exemplo, portanto role até a última lina, é lá que estará o motivo do erro.
2. **Caixa pontilhada azul**: Esta é a linha da mensagem de erro. Ela contém o motivo da exceção.
3. **Caixa pontilhada verde**: Após o nome da exceção está a mensagem de erro.
4. **Caixa amarela**: Mais acima há uma lista das chamadas de função realizadas. De baixo para cima temos a mais recente até a menos recente. Esta lista contém as seguintes informações:
	1. O caminho absoluto do arquivo (ou dos arquivos) envolvidos na execução do programa (`File`).
	2. O número da linha onde ocorreu o erro (`line`).
	3. O contexto onde o erro se origina. 

O Python possui alguns `tracebacks` que são bem comuns, conhecê-los ajuda a acelerar o processo de entendimento do problema. Falaremos dele mais adiante. No exemplo, vemos que a causa da exceção foi um `ValueError`, ou erro de valor, isto significa que um valor inválido foi utilizado em algum lugar. Ao lermos a mensagem do erro, somos informados que uma função nomeada `factorial()` não está definida para aceitar valores negativos. Claramente o valor inválido, portanto, é um valor negativo. Mas onde? Para descobrir, vamos para linha de cima. Nela lemos que uma variável `result` está tentando acrescentar um valor vinculado a uma variável `num` que utiliza `factorial()` para algum processamento antes de ser acrescentado (`append()`). Aqui temos uma pista que estamos trabalhando com listas. Perceba a indicação "^^^^" abaixo de `factoria(num)`; ela nos mostra exatamente a operação problemática. Subindo uma linha, vemos que este problema está no arquivo `debug_example_fatcorial.py`, na linha 7, na função `map_fatorial`. Nos certificamos disso ao avançar para linha de cima e vermos a indicação nos informando que `map_fatorial` é o retorno da função `main` e ocorre na linha 16 do mesmo arquivo. Por sua vez, a função `main()` está no mesmo módulo (`<module>`) ou seja no mesmo arquivo. 

Estas informações nos permitem presumir o seguinte :`factorial()` não pode processar um valor negativo, mas `result` está enviando esse valor mesmo assim. Este valor está armazenado em uma lista, pois `append()` é um método de lista. Portanto, a lista vinculada à `result` é o bug! Ela possui um número negativo que está sendo atribuída à variável `num`, muito provavelmente em um processo de iteração. Quando `factoria()` recebe `num` com valor inválido a exceção é levantada!    

Agora podemos checar o código:

```python
from math import factorial


def map_fatorial(numbers):
    result = []
    for num in numbers:
        result.append(factorial(num))

    return result


def main():
    numbers = [-1, 2, 3, 4, 5]

    # breakpoint()
    return map_fatorial(numbers=numbers)


if __name__ == "__main__":
    main()
```
Eis a lista com o bug: `numbers = [-1, 2, 3, 4, 5]` na função `main()`. O valor negativo inválido é `-1` ou o índice 0 da lista.

Ler o `tracebak` e compreender as exceções é vital para encontrar bugs. Está é a primeira estratégia mais básica de depuração que devemos adotar. No entanto, as coisas podem ficar muito mais complexas do que isso. Em caso complexos, precisamos de ferramentas que nos ajudem não apenas encontrar os erros, mas checar cada etapa de execução do código. Além disso, quanto maior nosso conhecimento acerca de como um código é executado, mais eficientes seremos na investigação de erros.   



---
## Referencias